2018-11-22 22:09:06,670 - flask.app - ERROR - Exception on /submit [POST]
Traceback (most recent call last):
  File "C:\Users\shirley.ng\AppData\Local\Continuum\anaconda3\envs\pyoct18\lib\site-packages\flask\app.py", line 2292, in wsgi_app
    response = self.full_dispatch_request()
  File "C:\Users\shirley.ng\AppData\Local\Continuum\anaconda3\envs\pyoct18\lib\site-packages\flask\app.py", line 1815, in full_dispatch_request
    rv = self.handle_user_exception(e)
  File "C:\Users\shirley.ng\AppData\Local\Continuum\anaconda3\envs\pyoct18\lib\site-packages\flask\app.py", line 1718, in handle_user_exception
    reraise(exc_type, exc_value, tb)
  File "C:\Users\shirley.ng\AppData\Local\Continuum\anaconda3\envs\pyoct18\lib\site-packages\flask\_compat.py", line 35, in reraise
    raise value
  File "C:\Users\shirley.ng\AppData\Local\Continuum\anaconda3\envs\pyoct18\lib\site-packages\flask\app.py", line 1813, in full_dispatch_request
    rv = self.dispatch_request()
  File "C:\Users\shirley.ng\AppData\Local\Continuum\anaconda3\envs\pyoct18\lib\site-packages\flask\app.py", line 1799, in dispatch_request
    return self.view_functions[rule.endpoint](**req.view_args)
  File "EntryForms.py", line 72, in signUp
    cursor.close()
UnboundLocalError: local variable 'cursor' referenced before assignment
2018-11-22 22:09:08,770 - flask.app - ERROR - An error occurred400 Bad Request: The browser (or proxy) sent a request that this server could not understand.
2018-11-22 22:09:08,774 - flask.app - ERROR - Exception on /submit [POST]
Traceback (most recent call last):
  File "C:\Users\shirley.ng\AppData\Local\Continuum\anaconda3\envs\pyoct18\lib\site-packages\flask\app.py", line 2292, in wsgi_app
    response = self.full_dispatch_request()
  File "C:\Users\shirley.ng\AppData\Local\Continuum\anaconda3\envs\pyoct18\lib\site-packages\flask\app.py", line 1815, in full_dispatch_request
    rv = self.handle_user_exception(e)
  File "C:\Users\shirley.ng\AppData\Local\Continuum\anaconda3\envs\pyoct18\lib\site-packages\flask\app.py", line 1718, in handle_user_exception
    reraise(exc_type, exc_value, tb)
  File "C:\Users\shirley.ng\AppData\Local\Continuum\anaconda3\envs\pyoct18\lib\site-packages\flask\_compat.py", line 35, in reraise
    raise value
  File "C:\Users\shirley.ng\AppData\Local\Continuum\anaconda3\envs\pyoct18\lib\site-packages\flask\app.py", line 1813, in full_dispatch_request
    rv = self.dispatch_request()
  File "C:\Users\shirley.ng\AppData\Local\Continuum\anaconda3\envs\pyoct18\lib\site-packages\flask\app.py", line 1799, in dispatch_request
    return self.view_functions[rule.endpoint](**req.view_args)
  File "EntryForms.py", line 72, in signUp
    cursor.close()
UnboundLocalError: local variable 'cursor' referenced before assignment
2018-11-22 22:10:10,815 - flask.app - ERROR - An error occurred400 Bad Request: The browser (or proxy) sent a request that this server could not understand.
2018-11-22 22:10:10,819 - flask.app - ERROR - Exception on /submit [POST]
Traceback (most recent call last):
  File "C:\Users\shirley.ng\AppData\Local\Continuum\anaconda3\envs\pyoct18\lib\site-packages\flask\app.py", line 2292, in wsgi_app
    response = self.full_dispatch_request()
  File "C:\Users\shirley.ng\AppData\Local\Continuum\anaconda3\envs\pyoct18\lib\site-packages\flask\app.py", line 1815, in full_dispatch_request
    rv = self.handle_user_exception(e)
  File "C:\Users\shirley.ng\AppData\Local\Continuum\anaconda3\envs\pyoct18\lib\site-packages\flask\app.py", line 1718, in handle_user_exception
    reraise(exc_type, exc_value, tb)
  File "C:\Users\shirley.ng\AppData\Local\Continuum\anaconda3\envs\pyoct18\lib\site-packages\flask\_compat.py", line 35, in reraise
    raise value
  File "C:\Users\shirley.ng\AppData\Local\Continuum\anaconda3\envs\pyoct18\lib\site-packages\flask\app.py", line 1813, in full_dispatch_request
    rv = self.dispatch_request()
  File "C:\Users\shirley.ng\AppData\Local\Continuum\anaconda3\envs\pyoct18\lib\site-packages\flask\app.py", line 1799, in dispatch_request
    return self.view_functions[rule.endpoint](**req.view_args)
  File "EntryForms.py", line 72, in signUp
    cursor.close()
UnboundLocalError: local variable 'cursor' referenced before assignment
2018-11-22 22:10:51,142 - flask.app - ERROR - An error occurred400 Bad Request: The browser (or proxy) sent a request that this server could not understand.
2018-11-22 22:10:51,142 - flask.app - ERROR - Exception on /submit [POST]
Traceback (most recent call last):
  File "C:\Users\shirley.ng\AppData\Local\Continuum\anaconda3\envs\pyoct18\lib\site-packages\flask\app.py", line 2292, in wsgi_app
    response = self.full_dispatch_request()
  File "C:\Users\shirley.ng\AppData\Local\Continuum\anaconda3\envs\pyoct18\lib\site-packages\flask\app.py", line 1815, in full_dispatch_request
    rv = self.handle_user_exception(e)
  File "C:\Users\shirley.ng\AppData\Local\Continuum\anaconda3\envs\pyoct18\lib\site-packages\flask\app.py", line 1718, in handle_user_exception
    reraise(exc_type, exc_value, tb)
  File "C:\Users\shirley.ng\AppData\Local\Continuum\anaconda3\envs\pyoct18\lib\site-packages\flask\_compat.py", line 35, in reraise
    raise value
  File "C:\Users\shirley.ng\AppData\Local\Continuum\anaconda3\envs\pyoct18\lib\site-packages\flask\app.py", line 1813, in full_dispatch_request
    rv = self.dispatch_request()
  File "C:\Users\shirley.ng\AppData\Local\Continuum\anaconda3\envs\pyoct18\lib\site-packages\flask\app.py", line 1799, in dispatch_request
    return self.view_functions[rule.endpoint](**req.view_args)
  File "EntryForms.py", line 72, in signUp
    cursor.close()
UnboundLocalError: local variable 'cursor' referenced before assignment
2018-11-22 22:10:57,534 - flask.app - ERROR - An error occurred400 Bad Request: The browser (or proxy) sent a request that this server could not understand.
2018-11-22 22:10:57,538 - flask.app - ERROR - Exception on /submit [POST]
Traceback (most recent call last):
  File "C:\Users\shirley.ng\AppData\Local\Continuum\anaconda3\envs\pyoct18\lib\site-packages\flask\app.py", line 2292, in wsgi_app
    response = self.full_dispatch_request()
  File "C:\Users\shirley.ng\AppData\Local\Continuum\anaconda3\envs\pyoct18\lib\site-packages\flask\app.py", line 1815, in full_dispatch_request
    rv = self.handle_user_exception(e)
  File "C:\Users\shirley.ng\AppData\Local\Continuum\anaconda3\envs\pyoct18\lib\site-packages\flask\app.py", line 1718, in handle_user_exception
    reraise(exc_type, exc_value, tb)
  File "C:\Users\shirley.ng\AppData\Local\Continuum\anaconda3\envs\pyoct18\lib\site-packages\flask\_compat.py", line 35, in reraise
    raise value
  File "C:\Users\shirley.ng\AppData\Local\Continuum\anaconda3\envs\pyoct18\lib\site-packages\flask\app.py", line 1813, in full_dispatch_request
    rv = self.dispatch_request()
  File "C:\Users\shirley.ng\AppData\Local\Continuum\anaconda3\envs\pyoct18\lib\site-packages\flask\app.py", line 1799, in dispatch_request
    return self.view_functions[rule.endpoint](**req.view_args)
  File "EntryForms.py", line 72, in signUp
    cursor.close()
UnboundLocalError: local variable 'cursor' referenced before assignment
2018-11-22 22:11:50,150 - flask.app - ERROR - An error occurred400 Bad Request: The browser (or proxy) sent a request that this server could not understand.
2018-11-22 22:11:50,158 - flask.app - ERROR - Exception on /submit [POST]
Traceback (most recent call last):
  File "C:\Users\shirley.ng\AppData\Local\Continuum\anaconda3\envs\pyoct18\lib\site-packages\flask\app.py", line 2292, in wsgi_app
    response = self.full_dispatch_request()
  File "C:\Users\shirley.ng\AppData\Local\Continuum\anaconda3\envs\pyoct18\lib\site-packages\flask\app.py", line 1815, in full_dispatch_request
    rv = self.handle_user_exception(e)
  File "C:\Users\shirley.ng\AppData\Local\Continuum\anaconda3\envs\pyoct18\lib\site-packages\flask\app.py", line 1718, in handle_user_exception
    reraise(exc_type, exc_value, tb)
  File "C:\Users\shirley.ng\AppData\Local\Continuum\anaconda3\envs\pyoct18\lib\site-packages\flask\_compat.py", line 35, in reraise
    raise value
  File "C:\Users\shirley.ng\AppData\Local\Continuum\anaconda3\envs\pyoct18\lib\site-packages\flask\app.py", line 1813, in full_dispatch_request
    rv = self.dispatch_request()
  File "C:\Users\shirley.ng\AppData\Local\Continuum\anaconda3\envs\pyoct18\lib\site-packages\flask\app.py", line 1799, in dispatch_request
    return self.view_functions[rule.endpoint](**req.view_args)
  File "EntryForms.py", line 72, in signUp
    cursor.close()
UnboundLocalError: local variable 'cursor' referenced before assignment
2018-11-22 22:12:41,447 - flask.app - ERROR - An error occurred400 Bad Request: The browser (or proxy) sent a request that this server could not understand.
